<?xml version="1.0" encoding="utf-8"?>
<!-- This URDF was automatically created by SolidWorks to URDF Exporter! Originally created by Stephen Brawner (brawner@gmail.com) 
     Commit Version: 1.5.1-0-g916b5db  Build Version: 1.5.7152.31018
     For more information, please see http://wiki.ros.org/sw_urdf_exporter -->
<robot
  name="big_arm">
  <link
    name="base_link">
    <inertial>
      <origin
        xyz="5.10334886736748E-36 -1.54939116262366E-18 0.0248239436619718"
        rpy="0 0 0" />
      <mass
        value="2.4419917555561" />
      <inertia
        ixx="0.150370490434844"
        ixy="-8.31151180314476E-36"
        ixz="-1.89588324363783E-34"
        iyy="0.150370490434844"
        iyz="8.4912872199433E-18"
        izz="0.290141728163054" />
    </inertial>
    <visual>
      <origin
        xyz="0 0 0"
        rpy="0 0 0" />
      <geometry>
        <mesh
          filename="package://robot/meshes/base_link.STL" />
      </geometry>
      <material
        name="">
        <color
          rgba="0.647058823529412 0.619607843137255 0.588235294117647 1" />
      </material>
    </visual>
    <collision>
      <origin
        xyz="0 0 0"
        rpy="0 0 0" />
      <geometry>
        <mesh
          filename="package://robot/meshes/base_link.STL" />
      </geometry>
    </collision>
  </link>

  <link name="world"/>
  <joint name="world_joint" type="fixed">
    <parent link="world" />
    <child link = "base_link" />
    <origin xyz="0.0 0.0 0.0" rpy="0.0 0.0 0.0" />
  </joint>


  <link
    name="link_1">
    <inertial>
      <origin
        xyz="-6.72935833564308E-17 5.41722740362335E-16 0.0562858835388927"
        rpy="0 0 0" />
      <mass
        value="1.24036308689963" />
      <inertia
        ixx="0.00602313752636761"
        ixy="2.1208125474502E-05"
        ixz="-1.04263858784396E-18"
        iyy="0.00579248437417585"
        iyz="-5.09141599596496E-19"
        izz="0.0098329939500295" />
    </inertial>
    <visual>
      <origin
        xyz="0 0 0"
        rpy="0 0 0" />
      <geometry>
        <mesh
          filename="package://robot/meshes/link_1.STL" />
      </geometry>
      <material
        name="">
        <color
          rgba="1 1 1 0.32" />
      </material>
    </visual>
    <collision>
      <origin
        xyz="0 0 0"
        rpy="0 0 0" />
      <geometry>
        <mesh
          filename="package://robot/meshes/link_1.STL" />
      </geometry>
    </collision>
  </link>
  <joint
    name="joint_base_1"
    type="continuous">
    <origin
      xyz="0 0 0.025"
      rpy="0 0 0" />
    <parent
      link="base_link" />
    <child
      link="link_1" />
    <axis
      xyz="0 0 1" />
    <limit
      lower="-3.14159"
      upper="3.14159"
      effort="10000"
      velocity="10" />
  </joint>
  <link
    name="link_2">
    <inertial>
      <origin
        xyz="0.19 3.7470027081099E-16 -3.12389003553903E-16"
        rpy="0 0 0" />
      <mass
        value="1.38058358126134" />
      <inertia
        ixx="0.00248849839246422"
        ixy="5.07965658468404E-18"
        ixz="-3.90312782094782E-18"
        iyy="0.0437476242743762"
        iyz="-8.67361737988404E-19"
        izz="0.0425687229272136" />
    </inertial>
    <visual>
      <origin
        xyz="0 0 0"
        rpy="0 0 0" />
      <geometry>
        <mesh
          filename="package://robot/meshes/link_2.STL" />
      </geometry>
      <material
        name="">
        <color
          rgba="1 1 1 0.32" />
      </material>
    </visual>
    <collision>
      <origin
        xyz="0 0 0"
        rpy="0 0 0" />
      <geometry>
        <mesh
          filename="package://robot/meshes/link_2.STL" />
      </geometry>
    </collision>
  </link>
  <joint
    name="joint_12"
    type="revolute">
    <origin
      xyz="0 0 0.11"
      rpy="-1.5708 -0.95024 -3.0507" />
    <parent
      link="link_1" />
    <child
      link="link_2" />
    <axis
      xyz="0 0 1" />
    <limit
      lower="0"
      upper="0"
      effort="10000"
      velocity="10" />
  </joint>
  <link
    name="link_3">
    <inertial>
      <origin
        xyz="0.190000000000009 1.0991207943789E-14 2.35922392732846E-16"
        rpy="0 0 0" />
      <mass
        value="0.492773406896242" />
      <inertia
        ixx="0.000993126064016739"
        ixy="-1.98629226131133E-19"
        ixz="-1.47383732822248E-18"
        iyy="0.00882828983439309"
        iyz="-3.79470760369927E-19"
        izz="0.00857639886635598" />
    </inertial>
    <visual>
      <origin
        xyz="0 0 0"
        rpy="0 0 0" />
      <geometry>
        <mesh
          filename="package://robot/meshes/link_3.STL" />
      </geometry>
      <material
        name="">
        <color
          rgba="1 1 1 0.32" />
      </material>
    </visual>
    <collision>
      <origin
        xyz="0 0 0"
        rpy="0 0 0" />
      <geometry>
        <mesh
          filename="package://robot/meshes/link_3.STL" />
      </geometry>
    </collision>
  </link>
  <joint
    name="joint_23"
    type="revolute">
    <origin
      xyz="0.38 0 0"
      rpy="0 0 -1.207" />
    <parent
      link="link_2" />
    <child
      link="link_3" />
    <axis
      xyz="0 0 1" />
    <limit
      lower="0"
      upper="0"
      effort="1000"
      velocity="10" />
  </joint>
  <link
    name="link_4">
    <inertial>
      <origin
        xyz="0.188502975963012 -0.0164677703024454 -0.0171883854493124"
        rpy="0 0 0" />
      <mass
        value="1.38058358126134" />
      <inertia
        ixx="0.00312638334029432"
        ixy="0.00354785475887284"
        ixz="0.00359649566474575"
        iyy="0.0434376808533928"
        iyz="-0.000323506272525106"
        izz="0.0422407814003671" />
    </inertial>
    <visual>
      <origin
        xyz="0 0 0"
        rpy="0 0 0" />
      <geometry>
        <mesh
          filename="package://robot/meshes/link_4.STL" />
      </geometry>
      <material
        name="">
        <color
          rgba="1 1 1 0.32" />
      </material>
    </visual>
    <collision>
      <origin
        xyz="0 0 0"
        rpy="0 0 0" />
      <geometry>
        <mesh
          filename="package://robot/meshes/link_4.STL" />
      </geometry>
    </collision>
  </link>
  <joint
    name="joint_34"
    type="revolute">
    <origin
      xyz="0.38 0 0"
      rpy="0 -0.090932 -0.98436" />
    <parent
      link="link_3" />
    <child
      link="link_4" />
    <axis
      xyz="0 0 1" />
    <limit
      lower="0"
      upper="0"
      effort="1000"
      velocity="10" />
  </joint>
  <link
    name="link_5">
    <inertial>
      <origin
        xyz="-0.0141429450104605 7.53233908579176E-08 0.00199995138060591"
        rpy="0 0 0" />
      <mass
        value="0.130378439395373" />
      <inertia
        ixx="9.85693744749924E-05"
        ixy="-2.23559602004266E-09"
        ixz="-7.5663588800688E-11"
        iyy="0.000116973092049288"
        iyz="5.32702014819344E-11"
        izz="0.0001866513337855" />
    </inertial>
    <visual>
      <origin
        xyz="0 0 0"
        rpy="0 0 0" />
      <geometry>
        <mesh
          filename="package://robot/meshes/link_5.STL" />
      </geometry>
      <material
        name="">
        <color
          rgba="1 1 1 0.32" />
      </material>
    </visual>
    <collision>
      <origin
        xyz="0 0 0"
        rpy="0 0 0" />
      <geometry>
        <mesh
          filename="package://robot/meshes/link_5.STL" />
      </geometry>
    </collision>
  </link>
  <joint
    name="joint_45"
    type="revolute">
    <origin
      xyz="0.37701 -0.032936 -0.034377"
      rpy="0.062559 -0.066036 2.3822" />
    <parent
      link="link_4" />
    <child
      link="link_5" />
    <axis
      xyz="0 0 1" />
    <limit
      lower="0"
      upper="0"
      effort="1000"
      velocity="10" />
  </joint>
  <link
    name="link_6">
    <inertial>
      <origin
        xyz="-4.97039481107964E-07 2.63088229068842E-06 0.0786774570131245"
        rpy="0 0 0" />
      <mass
        value="0.665759903912911" />
      <inertia
        ixx="0.000952789706275326"
        ixy="-1.38154320697555E-08"
        ixz="-8.31042935225815E-10"
        iyy="0.00095286060074004"
        iyz="4.52211814098408E-09"
        izz="0.00141997991990691" />
    </inertial>
    <visual>
      <origin
        xyz="0 0 0"
        rpy="0 0 0" />
      <geometry>
        <mesh
          filename="package://robot/meshes/link_6.STL" />
      </geometry>
      <material
        name="">
        <color
          rgba="1 1 1 0.32" />
      </material>
    </visual>
    <collision>
      <origin
        xyz="0 0 0"
        rpy="0 0 0" />
      <geometry>
        <mesh
          filename="package://robot/meshes/link_6.STL" />
      </geometry>
    </collision>
  </link>
  <joint
    name="joint_56"
    type="revolute">
    <origin
      xyz="-0.04 0 0.002"
      rpy="-2.3654 1.5708 0.77614" />
    <parent
      link="link_5" />
    <child
      link="link_6" />
    <axis
      xyz="0 0 1" />
    <limit
      lower="0"
      upper="0"
      effort="1000"
      velocity="10" />
  </joint>
  <link
    name="grip_1">
    <inertial>
      <origin
        xyz="0.0674233348638277 -0.00149730770397288 0.00988726780355913"
        rpy="0 0 0" />
      <mass
        value="0.11992363568227" />
      <inertia
        ixx="2.32996122881845E-05"
        ixy="-3.6096640394024E-12"
        ixz="4.42085269022021E-13"
        iyy="0.000147857015499886"
        iyz="8.71359919641666E-07"
        izz="0.000142235051121448" />
    </inertial>
    <visual>
      <origin
        xyz="0 0 0"
        rpy="0 0 0" />
      <geometry>
        <mesh
          filename="package://robot/meshes/grip_1.STL" />
      </geometry>
      <material
        name="">
        <color
          rgba="1 1 1 0.32" />
      </material>
    </visual>
    <collision>
      <origin
        xyz="0 0 0"
        rpy="0 0 0" />
      <geometry>
        <mesh
          filename="package://robot/meshes/grip_1.STL" />
      </geometry>
    </collision>
  </link>
  <joint
    name="joint_6_g1"
    type="revolute">
    <origin
      xyz="-0.011072 0.05897 0.091"
      rpy="-1.7211 -0.33932 1.7564" />
    <parent
      link="link_6" />
    <child
      link="grip_1" />
    <axis
      xyz="0 0 1" />
    <limit
      lower="0"
      upper="0"
      effort="1000"
      velocity="10" />
  </joint>
  <link
    name="grip_1b">
    <inertial>
      <origin
        xyz="0.0843265899344989 -0.00212380310637394 0.0099999996377477"
        rpy="0 0 0" />
      <mass
        value="0.141643537240913" />
      <inertia
        ixx="2.42692219268835E-05"
        ixy="1.63887843182053E-05"
        ixz="7.78137406188141E-12"
        iyy="0.000336749313354746"
        iyz="-5.98415142376405E-12"
        izz="0.000330285690314077" />
    </inertial>
    <visual>
      <origin
        xyz="0 0 0"
        rpy="0 0 0" />
      <geometry>
        <mesh
          filename="package://robot/meshes/grip_1b.STL" />
      </geometry>
      <material
        name="">
        <color
          rgba="1 1 1 0.32" />
      </material>
    </visual>
    <collision>
      <origin
        xyz="0 0 0"
        rpy="0 0 0" />
      <geometry>
        <mesh
          filename="package://robot/meshes/grip_1b.STL" />
      </geometry>
    </collision>
  </link>
  <joint
    name="joint_grip_1b"
    type="revolute">
    <origin
      xyz="0.11 0 0"
      rpy="0.011605 0.14985 -1.4932" />
    <parent
      link="grip_1" />
    <child
      link="grip_1b" />
    <axis
      xyz="0 0 1" />
    <limit
      lower="0"
      upper="0"
      effort="1000"
      velocity="10" />
  </joint>
  <link
    name="grip_2">
    <inertial>
      <origin
        xyz="0.0659446867940136 -0.0140429541455789 0.0100000004099546"
        rpy="0 0 0" />
      <mass
        value="0.119923642785374" />
      <inertia
        ixx="2.87087256812529E-05"
        ixy="2.54007949129357E-05"
        ixz="-6.35189378224036E-13"
        iyy="0.000142579853996741"
        iyz="-2.45328437956385E-12"
        izz="0.000142103089158568" />
    </inertial>
    <visual>
      <origin
        xyz="0 0 0"
        rpy="0 0 0" />
      <geometry>
        <mesh
          filename="package://robot/meshes/grip_2.STL" />
      </geometry>
      <material
        name="">
        <color
          rgba="1 1 1 0.32" />
      </material>
    </visual>
    <collision>
      <origin
        xyz="0 0 0"
        rpy="0 0 0" />
      <geometry>
        <mesh
          filename="package://robot/meshes/grip_2.STL" />
      </geometry>
    </collision>
  </link>
  <joint
    name="joint_6_g2"
    type="revolute">
    <origin
      xyz="0.05897 0.011072 0.091"
      rpy="-1.5708 -0.19278 0.1856" />
    <parent
      link="link_6" />
    <child
      link="grip_2" />
    <axis
      xyz="0 0 1" />
    <limit
      lower="0"
      upper="0"
      effort="1000"
      velocity="10" />
  </joint>
  <link
    name="grip_2b">
    <inertial>
      <origin
        xyz="0.0843265865207311 -0.00212380179885391 0.00999999957992204"
        rpy="0 0 0" />
      <mass
        value="0.141643614685743" />
      <inertia
        ixx="2.42692404977318E-05"
        ixy="1.63887852150154E-05"
        ixz="-1.45187447117269E-13"
        iyy="0.000336749419639376"
        iyz="-4.62085035355829E-12"
        izz="0.000330285797805327" />
    </inertial>
    <visual>
      <origin
        xyz="0 0 0"
        rpy="0 0 0" />
      <geometry>
        <mesh
          filename="package://robot/meshes/grip_2b.STL" />
      </geometry>
      <material
        name="">
        <color
          rgba="1 1 1 0.32" />
      </material>
    </visual>
    <collision>
      <origin
        xyz="0 0 0"
        rpy="0 0 0" />
      <geometry>
        <mesh
          filename="package://robot/meshes/grip_2b.STL" />
      </geometry>
    </collision>
  </link>
  <joint
    name="joint_grip_2b"
    type="revolute">
    <origin
      xyz="0.10759 -0.022911 0"
      rpy="0 0 -1.5817" />
    <parent
      link="grip_2" />
    <child
      link="grip_2b" />
    <axis
      xyz="0 0 1" />
    <limit
      lower="0"
      upper="0"
      effort="1000"
      velocity="10" />
  </joint>
  <link
    name="grip_3">
    <inertial>
      <origin
        xyz="0.0674233349821467 -0.000216683054989369 -0.00999765235365951"
        rpy="0 0 0" />
      <mass
        value="0.119923637058051" />
      <inertia
        ixx="2.32996122767126E-05"
        ixy="-3.01255348785664E-12"
        ixz="1.15039704239531E-12"
        iyy="0.0001479862078452"
        iyz="-1.27510854779785E-07"
        izz="0.000142105857428452" />
    </inertial>
    <visual>
      <origin
        xyz="0 0 0"
        rpy="0 0 0" />
      <geometry>
        <mesh
          filename="package://robot/meshes/grip_3.STL" />
      </geometry>
      <material
        name="">
        <color
          rgba="1 1 1 0.32" />
      </material>
    </visual>
    <collision>
      <origin
        xyz="0 0 0"
        rpy="0 0 0" />
      <geometry>
        <mesh
          filename="package://robot/meshes/grip_3.STL" />
      </geometry>
    </collision>
  </link>
  <joint
    name="joint_6_g3"
    type="revolute">
    <origin
      xyz="0.011072 -0.05897 0.091"
      rpy="-1.5491 -0.33932 -1.3852" />
    <parent
      link="link_6" />
    <child
      link="grip_3" />
    <axis
      xyz="0 0 1" />
    <limit
      lower="0"
      upper="0"
      effort="1000"
      velocity="10" />
  </joint>
  <link
    name="grip_3b">
    <inertial>
      <origin
        xyz="0.0843265835470308 -0.00212380359506137 -0.0100000017555446"
        rpy="0 0 0" />
      <mass
        value="0.141643615845273" />
      <inertia
        ixx="2.42692401970422E-05"
        ixy="1.6388779687381E-05"
        ixz="-2.83700056075674E-12"
        iyy="0.000336749373130495"
        iyz="-7.01396464170066E-12"
        izz="0.000330285749652679" />
    </inertial>
    <visual>
      <origin
        xyz="0 0 0"
        rpy="0 0 0" />
      <geometry>
        <mesh
          filename="package://robot/meshes/grip_3b.STL" />
      </geometry>
      <material
        name="">
        <color
          rgba="1 1 1 0.32" />
      </material>
    </visual>
    <collision>
      <origin
        xyz="0 0 0"
        rpy="0 0 0" />
      <geometry>
        <mesh
          filename="package://robot/meshes/grip_3b.STL" />
      </geometry>
    </collision>
  </link>
  <joint
    name="joint_grip_3b"
    type="revolute">
    <origin
      xyz="0.11 0 0"
      rpy="-0.013124 -0.017244 -0.9202" />
    <parent
      link="grip_3" />
    <child
      link="grip_3b" />
    <axis
      xyz="0 0 1" />
    <limit
      lower="0"
      upper="0"
      effort="1000"
      velocity="10" />
  </joint>
  <link
    name="grip_4">
    <inertial>
      <origin
        xyz="0.0674233355383608 -1.42527756957778E-09 0.0100000001980208"
        rpy="0 0 0" />
      <mass
        value="0.119923640551901" />
      <inertia
        ixx="2.32996121229523E-05"
        ixy="3.46372397723362E-12"
        ixz="-8.87942195128388E-13"
        iyy="0.000147988969529785"
        iyz="-2.64203844349206E-12"
        izz="0.000142103091352165" />
    </inertial>
    <visual>
      <origin
        xyz="0 0 0"
        rpy="0 0 0" />
      <geometry>
        <mesh
          filename="package://robot/meshes/grip_4.STL" />
      </geometry>
      <material
        name="">
        <color
          rgba="1 1 1 0.32" />
      </material>
    </visual>
    <collision>
      <origin
        xyz="0 0 0"
        rpy="0 0 0" />
      <geometry>
        <mesh
          filename="package://robot/meshes/grip_4.STL" />
      </geometry>
    </collision>
  </link>
  <joint
    name="joint_6_g4"
    type="revolute">
    <origin
      xyz="-0.05897 -0.011072 0.091"
      rpy="1.5708 -0.4026 -2.956" />
    <parent
      link="link_6" />
    <child
      link="grip_4" />
    <axis
      xyz="0 0 1" />
    <limit
      lower="0"
      upper="0"
      effort="1000"
      velocity="10" />
  </joint>
  <link
    name="grip_4b">
    <inertial>
      <origin
        xyz="0.0843265859870006 -0.0021238019435485 -0.0100000004854647"
        rpy="0 0 0" />
      <mass
        value="0.141643613852148" />
      <inertia
        ixx="2.42692402907718E-05"
        ixy="1.63887841722403E-05"
        ixz="-6.86254961946683E-13"
        iyy="0.000336749412376889"
        iyz="-4.57853621959074E-12"
        izz="0.000330285790627453" />
    </inertial>
    <visual>
      <origin
        xyz="0 0 0"
        rpy="0 0 0" />
      <geometry>
        <mesh
          filename="package://robot/meshes/grip_4b.STL" />
      </geometry>
      <material
        name="">
        <color
          rgba="1 1 1 0.32" />
      </material>
    </visual>
    <collision>
      <origin
        xyz="0 0 0"
        rpy="0 0 0" />
      <geometry>
        <mesh
          filename="package://robot/meshes/grip_4b.STL" />
      </geometry>
    </collision>
  </link>
  <joint
    name="joint_grip_4b"
    type="revolute">
    <origin
      xyz="0.11 0 0"
      rpy="3.1416 0 1.2805" />
    <parent
      link="grip_4" />
    <child
      link="grip_4b" />
    <axis
      xyz="0 0 1" />
    <limit
      lower="0"
      upper="0"
      effort="1000"
      velocity="10" />
  </joint>

  <!-- GAZEBO REFERENCES FOR BODIES-->

  <gazebo reference="base_link">
  <selfCollide>true</selfCollide>
    <mu1>100</mu1>
    <mu2>100</mu2>
    <kp>100000000</kp>
    <kd>1</kd>
    <material>Gazebo/Orange</material>
  </gazebo>  

  <gazebo reference="link_1">
  <selfCollide>true</selfCollide>
    <mu1>100</mu1>
    <mu2>100</mu2>
    <kp>100000000</kp>
    <kd>1</kd>
    <material>Gazebo/Orange</material>
  </gazebo> 

  <gazebo reference="link_2">
  <selfCollide>true</selfCollide>
    <mu1>0.1</mu1>
    <mu2>0.1</mu2>
    <kp>100000000</kp>
    <kd>0.1</kd>
    <material>Gazebo/Orange</material>
  </gazebo> 

  <gazebo reference="link_3">
  <selfCollide>true</selfCollide>
    <mu1>0.1</mu1>
    <mu2>0.1</mu2>
    <kp>100000000</kp>
    <kd>0.1</kd>
    <material>Gazebo/Orange</material>
  </gazebo> 

  <gazebo reference="link_4">
  <selfCollide>true</selfCollide>
    <mu1>0.1</mu1>
    <mu2>0.1</mu2>
    <kp>100000000</kp>
    <kd>0.1</kd>
    <material>Gazebo/Orange</material>
  </gazebo> 

  <gazebo reference="link_5">
  <selfCollide>true</selfCollide>
    <mu1>0.1</mu1>
    <mu2>0.1</mu2>
    <kp>100000000</kp>
    <kd>0.1</kd>
    <material>Gazebo/Orange</material>
  </gazebo> 

  <gazebo reference="link_6">
  <selfCollide>true</selfCollide>
    <mu1>0.1</mu1>
    <mu2>0.1</mu2>
    <kp>100000000</kp>
    <kd>0.1</kd>
    <material>Gazebo/Orange</material>
  </gazebo> 

  <gazebo reference="grip_1">
  <selfCollide>true</selfCollide>
    <mu1>100</mu1>
    <mu2>100</mu2>
    <kp>100000000</kp>
    <kd>1</kd>
    <material>Gazebo/Orange</material>
  </gazebo> 

  <gazebo reference="grip_1b">
  <selfCollide>true</selfCollide>
    <mu1>100</mu1>
    <mu2>100</mu2>
    <kp>100000000</kp>
    <kd>1</kd>
    <material>Gazebo/Orange</material>
  </gazebo> 

  <gazebo reference="grip_2">
  <selfCollide>true</selfCollide>
    <mu1>100</mu1>
    <mu2>100</mu2>
    <kp>100000000</kp>
    <kd>1</kd>
    <material>Gazebo/Orange</material>
  </gazebo> 

  <gazebo reference="grip_2b">
  <selfCollide>true</selfCollide>
    <mu1>100</mu1>
    <mu2>100</mu2>
    <kp>100000000</kp>
    <kd>1</kd>
    <material>Gazebo/Orange</material>
  </gazebo> 

  <gazebo reference="grip_3">
  <selfCollide>true</selfCollide>
    <mu1>100</mu1>
    <mu2>100</mu2>
    <kp>100000000</kp>
    <kd>1</kd>
    <material>Gazebo/Orange</material>
  </gazebo> 

  <gazebo reference="grip_3b">
  <selfCollide>true</selfCollide>
    <mu1>100</mu1>
    <mu2>100</mu2>
    <kp>100000000</kp>
    <kd>1</kd>
    <material>Gazebo/Orange</material>
  </gazebo>

  <gazebo reference="grip_4">
  <selfCollide>true</selfCollide>
    <mu1>100</mu1>
    <mu2>100</mu2>
    <kp>100000000</kp>
    <kd>100</kd>
    <material>Gazebo/Orange</material>
  </gazebo> 

  <gazebo reference="grip_4b">
  <selfCollide>true</selfCollide>
    <mu1>100</mu1>
    <mu2>100</mu2>
    <kp>100000000</kp>
    <kd>100</kd>
    <material>Gazebo/Orange</material>
  </gazebo> 

  <!-- ROS2 CONTROL -->
    <!--ros2_control name="GazeboSystem" type="system">
    <hardware>
      <plugin>gazebo_ros2_control/GazeboSystem</plugin>
    </hardware>    
    <joint name="joint_base_1">
      <command_interface name="position">
        <param name="min">-3.14159</param>
        <param name="max">3.14159</param>
      </command_interface>
      <state_interface name="position"/>
      <state_interface name="velocity"/>
      <state_interface name="effort"/>
    </joint>

    <joint name="joint_12">
      <command_interface name="position">
        <param name="min">-3.14159</param>
        <param name="max">3.14159</param>
      </command_interface>
      <state_interface name="position"/>
      <state_interface name="velocity"/>
      <state_interface name="effort"/>
    </joint>

    <joint name="joint_23">
      <command_interface name="position">
        <param name="min">-3.14159</param>
        <param name="max">3.14159</param>
      </command_interface>
      <state_interface name="position"/>
      <state_interface name="velocity"/>
      <state_interface name="effort"/>
    </joint>

    <joint name="joint_34">
      <command_interface name="position">
        <param name="min">-3.14159</param>
        <param name="max">3.14159</param>
      </command_interface>
      <state_interface name="position"/>
      <state_interface name="velocity"/>
      <state_interface name="effort"/>
    </joint>

    <joint name="joint_45">
      <command_interface name="position">
        <param name="min">-3.14159</param>
        <param name="max">3.14159</param>
      </command_interface>
      <state_interface name="position"/>
      <state_interface name="velocity"/>
      <state_interface name="effort"/>
    </joint>

    <joint name="joint_56">
      <command_interface name="position">
        <param name="min">-3.14159</param>
        <param name="max">3.14159</param>
      </command_interface>
      <state_interface name="position"/>
      <state_interface name="velocity"/>
      <state_interface name="effort"/>
    </joint>
  </ros2_control>
  
  
  
  
  <gazebo>
    <plugin filename="libgazebo_ros2_control.so" name="gazebo_ros2_control">
      <parameters>/home/legacy/Mechatronics Projects/big_arm_ws/src/robot/config/pos_controller.yaml</parameters>
    </plugin>
  </gazebo-->

  <!--Use Gazebo Joint State Publisher-->

  <gazebo>
    <plugin name="gazebo_ros_joint_state_publisher"
        filename="libgazebo_ros_joint_state_publisher.so">
        <update_rate>100</update_rate>
        <joint_name>joint_base_1</joint_name>
        <joint_name>joint_12</joint_name>
        <joint_name>joint_23</joint_name>
        <joint_name>joint_34</joint_name>
        <joint_name>joint_45</joint_name>
        <joint_name>joint_56</joint_name>
        <joint_name>joint_6_g1</joint_name>
        <joint_name>joint_6_g2</joint_name>
        <joint_name>joint_6_g3</joint_name>
        <joint_name>joint_6_g4</joint_name>
        <joint_name>joint_grip_1b</joint_name>
        <joint_name>joint_grip_2b</joint_name>
        <joint_name>joint_grip_3b</joint_name>
        <joint_name>joint_grip_4b</joint_name>

    </plugin>
  </gazebo>
</robot>