<?xml version="1.0" encoding="utf-8"?>
<!-- This URDF was automatically created by SolidWorks to URDF Exporter! Originally created by Stephen Brawner (brawner@gmail.com) 
     Commit Version: 1.5.1-0-g916b5db  Build Version: 1.5.7152.31018
     For more information, please see http://wiki.ros.org/sw_urdf_exporter -->
<robot
  name="big_arm_servos">
  <link
    name="base_link">
    <inertial>
      <origin
        xyz="5.10334886736748E-36 -1.54939116262366E-18 0.0248239436619718"
        rpy="0 0 0" />
      <mass
        value="2.4419917555561" />
      <inertia
        ixx="0.150370490434844"
        ixy="-8.31151180314476E-36"
        ixz="-1.89588324363783E-34"
        iyy="0.150370490434844"
        iyz="8.4912872199433E-18"
        izz="0.290141728163054" />
    </inertial>
    <visual>
      <origin
        xyz="0 0 0"
        rpy="0 0 0" />
      <geometry>
        <mesh
          filename="package://robot/meshes/base_link.STL" />
      </geometry>
      <material
        name="">
        <color
          rgba="0.647058823529412 0.619607843137255 0.588235294117647 1" />
      </material>
    </visual>
    <collision>
      <origin
        xyz="0 0 0"
        rpy="0 0 0" />
      <geometry>
        <mesh
          filename="package://robot/meshes/base_link.STL" />
      </geometry>
    </collision>
  </link>

  <link name="world"/>
  <joint name="world_joint" type="fixed">
    <parent link="world" />
    <child link = "base_link" />
    <origin xyz="0.0 0.0 0.0" rpy="0.0 0.0 0.0" />
  </joint>


  <link
    name="link_1">
    <inertial>
      <origin
        xyz="-6.72935833564308E-17 5.41722740362335E-16 0.0562858835388927"
        rpy="0 0 0" />
      <mass
        value="2.24036308689963" />
      <inertia
        ixx="0.00602313752636761"
        ixy="2.1208125474502E-05"
        ixz="-1.04263858784396E-18"
        iyy="0.00579248437417585"
        iyz="-5.09141599596496E-19"
        izz="0.0098329939500295" />
    </inertial>
    <visual>
      <origin
        xyz="0 0 0"
        rpy="0 0 0" />
      <geometry>
        <mesh
          filename="package://robot/meshes/link_1.STL" />
      </geometry>
      <material
        name="">
        <color
          rgba="1 1 1 0.32" />
      </material>
    </visual>
    <collision>
      <origin
        xyz="0 0 0"
        rpy="0 0 0" />
      <geometry>
        <mesh
          filename="package://robot/meshes/link_1.STL" />
      </geometry>
    </collision>
  </link>
  <joint
    name="joint_base_1"
    type="continuous">
    <origin
      xyz="0 0 0.025"
      rpy="0 0 3.14159" />
    <parent
      link="base_link" />
    <child
      link="link_1" />
    <axis
      xyz="0 0 1" />
    <limit
      lower="-3.14159"
      upper="3.14159"
      effort="10000"
      velocity="10" />
    <dynamics
      damping="0.3"
      friction="0.3" />
  </joint>
  <link
    name="link_2">
    <inertial>
      <origin
        xyz="0.19 3.7470027081099E-16 -3.12389003553903E-16"
        rpy="0 0 0" />
      <mass
        value="1.38058358126134" />
      <inertia
        ixx="0.00248849839246422"
        ixy="5.07965658468404E-18"
        ixz="-3.90312782094782E-18"
        iyy="0.0437476242743762"
        iyz="-8.67361737988404E-19"
        izz="0.0425687229272136" />
    </inertial>
    <visual>
      <origin
        xyz="0 0 0"
        rpy="0 0 0" />
      <geometry>
        <mesh
          filename="package://robot/meshes/link_2.STL" />
      </geometry>
      <material
        name="">
        <color
          rgba="1 1 1 0.32" />
      </material>
    </visual>
    <collision>
      <origin
        xyz="0 0 0"
        rpy="0 0 0" />
      <geometry>
        <mesh
          filename="package://robot/meshes/link_2.STL" />
      </geometry>
    </collision>
  </link>
  <joint
    name="joint_12"
    type="revolute">
    <!--origin
      xyz="0 0 0.11"
      rpy="-1.5708 -0.95024 -3.0507" /-->
    <origin
      xyz="0 0 0.11"
      rpy="-1.5708 0 -3.14159" />
    <parent
      link="link_1" />
    <child
      link="link_2" />
    <axis
      xyz="0 0 1" />
    <limit
      lower="-3.14159"
      upper="3.14159"
      effort="10000"
      velocity="10" />
    <dynamics
      damping="0.3"
      friction="0.3" />
  </joint>
  <link
    name="link_3">
    <inertial>
      <origin
        xyz="0.190000000000009 1.0991207943789E-14 2.35922392732846E-16"
        rpy="0 0 0" />
      <mass
        value="0.492773406896242" />
      <inertia
        ixx="0.000993126064016739"
        ixy="-1.98629226131133E-19"
        ixz="-1.47383732822248E-18"
        iyy="0.00882828983439309"
        iyz="-3.79470760369927E-19"
        izz="0.00857639886635598" />
    </inertial>
    <visual>
      <origin
        xyz="0 0 0"
        rpy="0 0 0" />
      <geometry>
        <mesh
          filename="package://robot/meshes/link_3.STL" />
      </geometry>
      <material
        name="">
        <color
          rgba="1 1 1 0.32" />
      </material>
    </visual>
    <collision>
      <origin
        xyz="0 0 0"
        rpy="0 0 0" />
      <geometry>
        <mesh
          filename="package://robot/meshes/link_3.STL" />
      </geometry>
    </collision>
  </link>
  <joint
    name="joint_23"
    type="revolute">
    <!--origin
      xyz="0.38 0 0"
      rpy="0 0 -1.207" /-->
    <origin
      xyz="0.38 0 0"
      rpy="0 0 0" />
    <parent
      link="link_2" />
    <child
      link="link_3" />
    <axis
      xyz="0 0 1" />
    <limit
      lower="-3.14159"
      upper="3.14159"
      effort="1000"
      velocity="10" />
    <dynamics
      damping="0.3"
      friction="0.3" />
  </joint>
  <link
    name="link_4">
    <inertial>
      <!--origin
        xyz="0.188502975963012 -0.0164677703024454 -0.0171883854493124"
        rpy="0 0 0" /-->
      <origin
        xyz="0.188502975963012 -0.0164677703024454 -0.0171883854493124"
        rpy="0 0 0" />
      <mass
        value="1.38058358126134" />
      <inertia
        ixx="0.00312638334029432"
        ixy="0.00354785475887284"
        ixz="0.00359649566474575"
        iyy="0.0434376808533928"
        iyz="-0.000323506272525106"
        izz="0.0422407814003671" />
    </inertial>
    <visual>
      <origin
        xyz="0 0 0"
        rpy="0 -0.1 0.08" />
      <geometry>
        <mesh
          filename="package://robot/meshes/link_4.STL" />
      </geometry>
      <material
        name="">
        <color
          rgba="1 1 1 0.32" />
      </material>
    </visual>
    <collision>
      <origin
        xyz="0 0 0"
        rpy="0 -0.1 0" />
      <geometry>
        <mesh
          filename="package://robot/meshes/link_4.STL" />
      </geometry>
    </collision>
  </link>
  <joint
    name="joint_34"
    type="revolute">
    <!--origin
      xyz="0.38 0 0"
      rpy="0 -0.090932 -0.98436" /-->
    <origin
      xyz="0.38 0 0"
      rpy="0 0 0" />
    <parent
      link="link_3" />
    <child
      link="link_4" />
    <axis
      xyz="0 0 1" />
    <limit
      lower="-3.14159"
      upper="3.14159"
      effort="1000"
      velocity="10" />
    <dynamics
      damping="0.3"
      friction="0.3" />
  </joint>
  <link
    name="link_5">
    <inertial>
    <!--origin
        xyz="-0.0141429450104605 7.53233908579176E-08 0.00199995138060591"
        rpy="0 0 0" /-->
      <origin
        xyz="0 0 0"
        rpy="0 0 0" />
      <mass
        value="0.130378439395373" />
      <inertia
        ixx="9.85693744749924E-05"
        ixy="-2.23559602004266E-09"
        ixz="-7.5663588800688E-11"
        iyy="0.000116973092049288"
        iyz="5.32702014819344E-11"
        izz="0.0001866513337855" />
    </inertial>
    <visual>
      <origin
        xyz="0 0 0"
        rpy="0 0 0" />
      <geometry>
        <mesh
          filename="package://robot/meshes/link_5.STL" />
      </geometry>
      <material
        name="">
        <color
          rgba="1 1 1 0.32" />
      </material>
    </visual>
    <collision>
      <origin
        xyz="0 0 0"
        rpy="0 0 0" />
      <geometry>
        <mesh
          filename="package://robot/meshes/link_5.STL" />
      </geometry>
    </collision>
  </link>
  <joint
    name="joint_45"
    type="revolute">
    <origin
      xyz="0.37701 0 0"
      rpy="0 0 -1.57079" />
    <!--origin
      xyz="0.37701 -0.032936 -0.034377"
      rpy="0.062559 -0.066036 2.3822" /-->
    <parent
      link="link_4" />
    <child
      link="link_5" />
    <axis
      xyz="0 0 1" />
    <limit
      lower="-3.14159"
      upper="3.14159"
      effort="1000"
      velocity="10" />
    <dynamics
      damping="0.3"
      friction="0.3" />
  </joint>
  <link
    name="link_6">
    <inertial>
      <origin
        xyz="-4.97039481107964E-07 2.63088229068842E-06 0.0786774570131245"
        rpy="0 0 0" />
      <mass
        value="0.665759903912911" />
      <inertia
        ixx="0.000952789706275326"
        ixy="-1.38154320697555E-08"
        ixz="-8.31042935225815E-10"
        iyy="0.00095286060074004"
        iyz="4.52211814098408E-09"
        izz="0.00141997991990691" />
    </inertial>
    <visual>
      <origin
        xyz="0 0 0"
        rpy="0 0 0" />
      <geometry>
        <mesh
          filename="package://robot/meshes/link_6.STL" />
      </geometry>
      <material
        name="">
        <color
          rgba="1 1 1 0.32" />
      </material>
    </visual>
    <collision>
      <origin
        xyz="0 0 0"
        rpy="0 0 0" />
      <geometry>
        <mesh
          filename="package://robot/meshes/link_6.STL" />
      </geometry>
    </collision>
  </link>
  <joint
    name="joint_56"
    type="revolute">
    <origin
      xyz="0 0 0.002"
      rpy="-2.3654 1.5708 -0.7853981634" />
    <parent
      link="link_5" />
    <child
      link="link_6" />
    <axis
      xyz="0 0 1" />
    <limit
      lower="-3.14159"
      upper="3.14159"
      effort="1000"
      velocity="10" />
    <dynamics
      damping="0.1"
      friction="0.1" />
  </joint>

  <link
    name="grip_2">
    <inertial>
      <origin
        xyz="0.0659446867940136 -0.0140429541455789 0.0100000004099546"
        rpy="0 0 0" />
      <mass
        value="0.119923642785374" />
      <inertia
        ixx="2.87087256812529E-05"
        ixy="2.54007949129357E-05"
        ixz="-6.35189378224036E-13"
        iyy="0.000142579853996741"
        iyz="-2.45328437956385E-12"
        izz="0.000142103089158568" />
    </inertial>
    <visual>
      <origin
        xyz="0 0 0"
        rpy="0 0 0" />
      <geometry>
        <mesh
          filename="package://robot/meshes/grip_2.STL" />
      </geometry>
      <material
        name="">
        <color
          rgba="1 1 1 0.32" />
      </material>
    </visual>
    <collision>
      <origin
        xyz="0 0 0"
        rpy="0 0 0" />
      <geometry>
        <mesh
          filename="package://robot/meshes/grip_2.STL" />
      </geometry>
    </collision>
  </link>
  <joint
    name="joint_6_g2"
    type="revolute">
    <origin
      xyz="0.05897 0.011072 0.091"
      rpy="-1.5708 -0.19278 0.1856" />
    <parent
      link="link_6" />
    <child
      link="grip_2" />
    <axis
      xyz="0 0 1" />
    <limit
      lower="-3.14159"
      upper="3.14159"
      effort="1000"
      velocity="10" />
    <dynamics
      damping="0.3"
      friction="0.3" />
  </joint>
  <link
    name="grip_2b">
    <inertial>
      <origin
        xyz="0.0843265865207311 -0.00212380179885391 0.00999999957992204"
        rpy="0 0 0" />
      <mass
        value="0.141643614685743" />
      <inertia
        ixx="2.42692404977318E-05"
        ixy="1.63887852150154E-05"
        ixz="-1.45187447117269E-13"
        iyy="0.000336749419639376"
        iyz="-4.62085035355829E-12"
        izz="0.000330285797805327" />
    </inertial>
    <visual>
      <origin
        xyz="0 0 0"
        rpy="0 0 0" />
      <geometry>
        <mesh
          filename="package://robot/meshes/grip_2b.STL" />
      </geometry>
      <material
        name="">
        <color
          rgba="1 1 1 0.32" />
      </material>
    </visual>
    <collision>
      <origin
        xyz="0 0 0"
        rpy="0 0 0" />
      <geometry>
        <mesh
          filename="package://robot/meshes/grip_2b.STL" />
      </geometry>
    </collision>
  </link>
  <joint
    name="joint_grip_2b"
    type="revolute">
    <origin
      xyz="0.10759 -0.022911 0"
      rpy="0 0 -1.5817" />
    <parent
      link="grip_2" />
    <child
      link="grip_2b" />
    <axis
      xyz="0 0 1" />
    <limit
      lower="-3.14159"
      upper="3.14159"
      effort="1000"
      velocity="10" />
    <dynamics
      damping="0.3"
      friction="0.3" />
  </joint>
  <link
    name="grip_4">
    <inertial>
      <origin
        xyz="0.0674233355383608 -1.42527756957778E-09 0.0100000001980208"
        rpy="0 0 0" />
      <mass
        value="0.119923640551901" />
      <inertia
        ixx="2.32996121229523E-05"
        ixy="3.46372397723362E-12"
        ixz="-8.87942195128388E-13"
        iyy="0.000147988969529785"
        iyz="-2.64203844349206E-12"
        izz="0.000142103091352165" />
    </inertial>
    <visual>
      <origin
        xyz="0 0 0"
        rpy="0 0 0" />
      <geometry>
        <mesh
          filename="package://robot/meshes/grip_4.STL" />
      </geometry>
      <material
        name="">
        <color
          rgba="1 1 1 0.32" />
      </material>
    </visual>
    <collision>
      <origin
        xyz="0 0 0"
        rpy="0 0 0" />
      <geometry>
        <mesh
          filename="package://robot/meshes/grip_4.STL" />
      </geometry>
    </collision>
  </link>
  <joint
    name="joint_6_g4"
    type="revolute">
    <origin
      xyz="-0.05897 -0.011072 0.091"
      rpy="1.5708 -0.4026 -2.956" />
    <parent
      link="link_6" />
    <child
      link="grip_4" />
    <axis
      xyz="0 0 1" />
    <limit
      lower="-3.14159"
      upper="3.14159"
      effort="1000"
      velocity="10" />
    <dynamics
      damping="0.3"
      friction="0.3" />
  </joint>
  <link
    name="grip_4b">
    <inertial>
      <origin
        xyz="0.0843265859870006 -0.0021238019435485 -0.0100000004854647"
        rpy="0 0 0" />
      <mass
        value="0.141643613852148" />
      <inertia
        ixx="2.42692402907718E-05"
        ixy="1.63887841722403E-05"
        ixz="-6.86254961946683E-13"
        iyy="0.000336749412376889"
        iyz="-4.57853621959074E-12"
        izz="0.000330285790627453" />
    </inertial>
    <visual>
      <origin
        xyz="0 0 0"
        rpy="0 0 0" />
      <geometry>
        <mesh
          filename="package://robot/meshes/grip_4b.STL" />
      </geometry>
      <material
        name="">
        <color
          rgba="1 1 1 0.32" />
      </material>
    </visual>
    <collision>
      <origin
        xyz="0 0 0"
        rpy="0 0 0" />
      <geometry>
        <mesh
          filename="package://robot/meshes/grip_4b.STL" />
      </geometry>
    </collision>
  </link>
  <joint
    name="joint_grip_4b"
    type="revolute">
    <origin
      xyz="0.11 0 0"
      rpy="3.1416 0 1.2805" />
    <parent
      link="grip_4" />
    <child
      link="grip_4b" />
    <axis
      xyz="0 0 1" />
    <limit
      lower="-3.14159"
      upper="3.14159"
      effort="1000"
      velocity="10" />
    <dynamics
      damping="0.3"
      friction="0.3" />
  </joint>

  <!-- CAMERA -->

  <link
    name="camera_link">
    <inertial>
      <origin
        xyz="0 0 0"
        rpy="0 0 0" />
      <mass
        value="0.03" />
      <inertia
        ixx="1E-5"
        ixy="-6.30057515429682E-19"
        ixz="9.52689050201753E-19"
        iyy="1E-5"
        iyz="-2.5410988417629E-20"
        izz="1E-5" />
    </inertial>
    <visual>
      <origin
        xyz="0 0 0"
        rpy="0 0 0" />
    <geometry>
      <box size="0.02 0.02 0.02"/>
    </geometry>
      <material
        name="">
        <color
          rgba="1 0.913725490196078 0.0313725490196078 1" />
      </material>
    </visual>
    <collision>
      <origin
        xyz="0 0 0"
        rpy="0 0 0" />
      <geometry>
          <box size="0.02 0.02 0.02"/>
      </geometry>
    </collision>
  </link>

  <joint name="camera_joint" type="fixed">
    <parent link="link_1" />
    <child link = "camera_link" />
    <origin xyz="0.15 0.0 0.05" rpy="0.0 0.0 0.0" />
  </joint>

  <gazebo reference="camera_link">
    <sensor type="camera" name="camera1">
      <update_rate>30.0</update_rate>
      <camera name="head">
        <horizontal_fov>1.3962634</horizontal_fov>
        <image>
          <width>800</width>
          <height>800</height>
          <format>R8G8B8</format>
        </image>
        <clip>
          <near>0.02</near>
          <far>300</far>
        </clip>
        <noise>
          <type>gaussian</type>
          <!-- Noise is sampled independently per pixel on each frame.
               That pixel's noise value is added to each of its color
               channels, which at that point lie in the range [0,1]. -->
          <mean>0.0</mean>
          <stddev>0.007</stddev>
        </noise>
      </camera>
      <plugin name="camera_controller" filename="libgazebo_ros_camera.so">
        <alwaysOn>true</alwaysOn>
        <updateRate>0.0</updateRate>
        <cameraName>big_arm/camera1</cameraName>
        <imageTopicName>image_raw</imageTopicName>
        <cameraInfoTopicName>camera_info</cameraInfoTopicName>
        <frameName>camera_link</frameName>
        <hackBaseline>0.07</hackBaseline>
        <distortionK1>0.0</distortionK1>
        <distortionK2>0.0</distortionK2>
        <distortionK3>0.0</distortionK3>
        <distortionT1>0.0</distortionT1>
        <distortionT2>0.0</distortionT2>
      </plugin>
    </sensor>
  </gazebo>

   <!-- GAZEBO REFERENCES FOR BODIES-->

  <gazebo reference="camera_link">
  <selfCollide>true</selfCollide>
    <mu1>0.1</mu1>
    <mu2>0.1</mu2>
    <kp>100000</kp>
    <kd>0.1</kd>
    <material>Gazebo/Brown</material>
  </gazebo>  

  <gazebo reference="base_link">
  <selfCollide>true</selfCollide>
    <mu1>0.1</mu1>
    <mu2>0.1</mu2>
    <kp>100000</kp>
    <kd>0.1</kd>
    <material>Gazebo/Orange</material>
  </gazebo>  

  <gazebo reference="link_1">
  <selfCollide>true</selfCollide>
    <mu1>0.1</mu1>
    <mu2>0.1</mu2>
    <kp>100000</kp>
    <kd>0.1</kd>
    <material>Gazebo/Orange</material>
  </gazebo> 

  <gazebo reference="link_2">
  <selfCollide>true</selfCollide>
    <mu1>0.1</mu1>
    <mu2>0.1</mu2>
    <kp>10000</kp>
    <kd>0.1</kd>
    <material>Gazebo/Orange</material>
  </gazebo> 

  <gazebo reference="link_3">
  <selfCollide>true</selfCollide>
    <mu1>0.1</mu1>
    <mu2>0.1</mu2>
    <kp>100000</kp>
    <kd>0.1</kd>
    <material>Gazebo/Orange</material>
  </gazebo> 

  <gazebo reference="link_4">
  <selfCollide>true</selfCollide>
    <mu1>0.1</mu1>
    <mu2>0.1</mu2>
    <kp>100000</kp>
    <kd>0.1</kd>
    <material>Gazebo/Orange</material>
  </gazebo> 

  <gazebo reference="link_5">
  <selfCollide>true</selfCollide>
    <mu1>0.1</mu1>
    <mu2>0.1</mu2>
    <kp>100000</kp>
    <kd>0.1</kd>
    <material>Gazebo/Orange</material>
  </gazebo> 

  <gazebo reference="link_6">
  <selfCollide>true</selfCollide>
    <mu1>0.1</mu1>
    <mu2>0.1</mu2>
    <kp>100000</kp>
    <kd>0.1</kd>
    <material>Gazebo/Orange</material>
  </gazebo> 

  <gazebo reference="grip_2">
  <selfCollide>true</selfCollide>
    <mu1>100</mu1>
    <mu2>100</mu2>
    <kp>100000</kp>
    <kd>1</kd>
    <material>Gazebo/Orange</material>
  </gazebo> 

  <gazebo reference="grip_2b">
  <selfCollide>true</selfCollide>
    <mu1>100</mu1>
    <mu2>100</mu2>
    <kp>100000</kp>
    <kd>1</kd>
    <material>Gazebo/Orange</material>
  </gazebo> 

  <gazebo reference="grip_4">
  <selfCollide>true</selfCollide>
    <mu1>100</mu1>
    <mu2>100</mu2>
    <kp>100000000</kp>
    <kd>100</kd>
    <material>Gazebo/Orange</material>
  </gazebo> 

  <gazebo reference="grip_4b">
  <selfCollide>true</selfCollide>
    <mu1>100</mu1>
    <mu2>100</mu2>
    <kp>100000000</kp>
    <kd>100</kd>
    <material>Gazebo/Orange</material>
  </gazebo> 

  <!-- ROS2 CONTROL -->
    <ros2_control name="GazeboSystem" type="system">
    <hardware>
      <plugin>gazebo_ros2_control/GazeboSystem</plugin>
    </hardware>    
    <joint name="joint_base_1">
      <command_interface name="position">
        <param name="min">-3.14159</param>
        <param name="max">3.14159</param>
      </command_interface>
      <state_interface name="position"/>
      <state_interface name="velocity"/>
      <state_interface name="effort"/>
    </joint>

    <joint name="joint_12">
      <command_interface name="position">
        <param name="min">-3.14159</param>
        <param name="max">3.14159</param>
      </command_interface>
      <state_interface name="position"/>
      <state_interface name="velocity"/>
      <state_interface name="effort"/>
    </joint>

    <joint name="joint_23">
      <command_interface name="position">
        <param name="min">-3.14159</param>
        <param name="max">3.14159</param>
      </command_interface>
      <state_interface name="position"/>
      <state_interface name="velocity"/>
      <state_interface name="effort"/>
    </joint>

    <joint name="joint_34">
      <command_interface name="position">
        <param name="min">-3.14159</param>
        <param name="max">3.14159</param>
      </command_interface>
      <state_interface name="position"/>
      <state_interface name="velocity"/>
      <state_interface name="effort"/>
    </joint>

    <joint name="joint_45">
      <command_interface name="position">
        <param name="min">-3.14159</param>
        <param name="max">3.14159</param>
      </command_interface>
      <state_interface name="position"/>
      <state_interface name="velocity"/>
      <state_interface name="effort"/>
    </joint>

    <joint name="joint_56">
      <command_interface name="position">
        <param name="min">-3.14159</param>
        <param name="max">3.14159</param>
      </command_interface>
      <state_interface name="position"/>
      <state_interface name="velocity"/>
      <state_interface name="effort"/>
    </joint>

    <joint name="joint_6_g2">
      <command_interface name="position">
        <param name="min">-3.14159</param>
        <param name="max">3.14159</param>
      </command_interface>
      <state_interface name="position"/>
      <state_interface name="velocity"/>
      <state_interface name="effort"/>
    </joint>

    <joint name="joint_6_g4">
      <command_interface name="position">
        <param name="min">-3.14159</param>
        <param name="max">3.14159</param>
      </command_interface>
      <state_interface name="position"/>
      <state_interface name="velocity"/>
      <state_interface name="effort"/>
    </joint>

    <joint name="joint_grip_2b">
      <command_interface name="position">
        <param name="min">-3.14159</param>
        <param name="max">3.14159</param>
      </command_interface>
      <state_interface name="position"/>
      <state_interface name="velocity"/>
      <state_interface name="effort"/>
    </joint>

    <joint name="joint_grip_4b">
      <command_interface name="position">
        <param name="min">-3.14159</param>
        <param name="max">3.14159</param>
      </command_interface>
      <state_interface name="position"/>
      <state_interface name="velocity"/>
      <state_interface name="effort"/>
    </joint>


  </ros2_control>
  
  
  
  <gazebo>
    <plugin filename="libgazebo_ros2_control.so" name="gazebo_ros2_control">
      <parameters>/home/legacy/Mechatronics Projects/big_arm_ws/src/robot/config/pos_controller.yaml</parameters>
    </plugin>
  </gazebo>

  <!--Use Gazebo Joint State Publisher-->

  <gazebo>
    <plugin name="gazebo_ros_joint_state_publisher"
        filename="libgazebo_ros_joint_state_publisher.so">
        <update_rate>100</update_rate>
        <joint_name>camera_joint</joint_name>
    </plugin>
  </gazebo>
</robot>